Workbook

Sheet PLANIFICACION_MENSUAL
A1: RUT | B1: Estado | C1: NOMBRE | D1: SERVICIO | E1: FECHA | F1: DIA | G1: SEMANA | H1: TURNO | I1: ESTADO_DIA | J1: H_INICIO | K1: H_TERMINO | L1: DURACION | M1: Horas diarias | N1: Minutos Colacion | O1: hora colacion | P1: Total Horas Trabajadas | Q1: HORAS TRABAJADAS | R1: DESCANSO 1 | S1: DESCANSO 2 | T1: SALIDA COLACION | U1: ENTRADA COLACION | V1: TIEMPO COLACION
A2: 11111111-1 | B2: Activo | C2: ANA PÉREZ (EJEMPLO) | D2: EXAMEN Y PROCEDIMIENTOS | E2: 46296 | F2: Jueves | G2: 46293 | H2: Tarde C/sábado | I2: TRABAJA | J2: 0.5 | K2: 0.83333333 | L2: =IF(COUNT(J2:K2)=2,K2-J2,0) | M2: =L2*24 | N2: 60 | O2: =N2/60 | P2: =M2-O2 | Q2: =SUMIFS($P:$P,$A:$A,A2,$G:$G,G2) | R2: 0.58333333 | S2: 0.76041667 | T2: 0.63541667 | U2: 0.67708333 | V2: =IF(COUNT(T2:U2)=2,ROUND((U2-T2)*1440,0),0)
A3: 11111111-1 | B3: Activo | C3: ANA PÉREZ (EJEMPLO) | D3: EXAMEN Y PROCEDIMIENTOS | E3: 46297 | F3: Viernes | G3: 46293 | H3: Tarde C/sábado | I3: TRABAJA | J3: 0.5 | K3: 0.83333333 | L3: =IF(COUNT(J3:K3)=2,K3-J3,0) | M3: =L3*24 | N3: 60 | O3: =N3/60 | P3: =M3-O3 | Q3: =SUMIFS($P:$P,$A:$A,A3,$G:$G,G3) | R3: 0.58333333 | S3: 0.76041667 | T3: 0.63541667 | U3: 0.67708333 | V3: =IF(COUNT(T3:U3)=2,ROUND((U3-T3)*1440,0),0)
A4: 11111111-1 | B4: Activo | C4: ANA PÉREZ (EJEMPLO) | D4: EXAMEN Y PROCEDIMIENTOS | E4: 46298 | F4: Sábado | G4: 46293 | H4: Tarde C/sábado | I4: TRABAJA | J4: 0.33333333 | K4: 0.58333333 | L4: =IF(COUNT(J4:K4)=2,K4-J4,0) | M4: =L4*24 | N4: 30 | O4: =N4/60 | P4: =M4-O4 | Q4: =SUMIFS($P:$P,$A:$A,A4,$G:$G,G4) | T4: 0.4375 | U4: 0.45833333 | V4: =IF(COUNT(T4:U4)=2,ROUND((U4-T4)*1440,0),0)
A5: 11111111-1 | B5: Activo | C5: ANA PÉREZ (EJEMPLO) | D5: EXAMEN Y PROCEDIMIENTOS | E5: 46300 | F5: Lunes | G5: 46300 | H5: Mañana S/sábado | I5: TRABAJA | J5: 0.33333333 | K5: 0.72916667 | L5: =IF(COUNT(J5:K5)=2,K5-J5,0) | M5: =L5*24 | N5: 60 | O5: =N5/60 | P5: =M5-O5 | Q5: =SUMIFS($P:$P,$A:$A,A5,$G:$G,G5) | R5: 0.44791667 | S5: 0.67708333 | T5: 0.55208333 | U5: 0.59375 | V5: =IF(COUNT(T5:U5)=2,ROUND((U5-T5)*1440,0),0)
A6: 11111111-1 | B6: Activo | C6: ANA PÉREZ (EJEMPLO) | D6: EXAMEN Y PROCEDIMIENTOS | E6: 46301 | F6: Martes | G6: 46300 | H6: Mañana S/sábado | I6: TRABAJA | J6: 0.33333333 | K6: 0.72916667 | L6: =IF(COUNT(J6:K6)=2,K6-J6,0) | M6: =L6*24 | N6: 60 | O6: =N6/60 | P6: =M6-O6 | Q6: =SUMIFS($P:$P,$A:$A,A6,$G:$G,G6) | R6: 0.44791667 | S6: 0.67708333 | T6: 0.55208333 | U6: 0.59375 | V6: =IF(COUNT(T6:U6)=2,ROUND((U6-T6)*1440,0),0)
A7: 11111111-1 | B7: Activo | C7: ANA PÉREZ (EJEMPLO) | D7: EXAMEN Y PROCEDIMIENTOS | E7: 46302 | F7: Miércoles | G7: 46300 | H7: Mañana S/sábado | I7: TRABAJA | J7: 0.33333333 | K7: 0.72916667 | L7: =IF(COUNT(J7:K7)=2,K7-J7,0) | M7: =L7*24 | N7: 60 | O7: =N7/60 | P7: =M7-O7 | Q7: =SUMIFS($P:$P,$A:$A,A7,$G:$G,G7) | R7: 0.42708333 | S7: 0.64583333 | T7: 0.47916667 | U7: 0.52083333 | V7: =IF(COUNT(T7:U7)=2,ROUND((U7-T7)*1440,0),0)
A8: 11111111-1 | B8: Activo | C8: ANA PÉREZ (EJEMPLO) | D8: EXAMEN Y PROCEDIMIENTOS | E8: 46303 | F8: Jueves | G8: 46300 | H8: Mañana S/sábado | I8: TRABAJA | J8: 0.33333333 | K8: 0.72916667 | L8: =IF(COUNT(J8:K8)=2,K8-J8,0) | M8: =L8*24 | N8: 60 | O8: =N8/60 | P8: =M8-O8 | Q8: =SUMIFS($P:$P,$A:$A,A8,$G:$G,G8) | R8: 0.42708333 | S8: 0.63541667 | T8: 0.47916667 | U8: 0.52083333 | V8: =IF(COUNT(T8:U8)=2,ROUND((U8-T8)*1440,0),0)
A9: 11111111-1 | B9: Activo | C9: ANA PÉREZ (EJEMPLO) | D9: EXAMEN Y PROCEDIMIENTOS | E9: 46304 | F9: Viernes | G9: 46300 | H9: Mañana S/sábado | I9: TRABAJA | J9: 0.33333333 | K9: 0.70833333 | L9: =IF(COUNT(J9:K9)=2,K9-J9,0) | M9: =L9*24 | N9: 60 | O9: =N9/60 | P9: =M9-O9 | Q9: =SUMIFS($P:$P,$A:$A,A9,$G:$G,G9) | R9: 0.44791667 | S9: 0.66666667 | T9: 0.54166667 | U9: 0.58333333 | V9: =IF(COUNT(T9:U9)=2,ROUND((U9-T9)*1440,0),0)
A10: 11111111-1 | B10: Activo | C10: ANA PÉREZ (EJEMPLO) | D10: EXAMEN Y PROCEDIMIENTOS | E10: 46305 | F10: Sábado | G10: 46300 | H10: Mañana S/sábado | I10: LIBRE | L10: =IF(COUNT(J10:K10)=2,K10-J10,0) | M10: =L10*24 | N10: 0 | O10: =N10/60 | P10: =M10-O10 | Q10: =SUMIFS($P:$P,$A:$A,A10,$G:$G,G10) | V10: =IF(COUNT(T10:U10)=2,ROUND((U10-T10)*1440,0),0)
A11: 11111111-1 | B11: Activo | C11: ANA PÉREZ (EJEMPLO) | D11: EXAMEN Y PROCEDIMIENTOS | E11: 46307 | F11: Lunes | G11: 46307 | H11: Mañana S/sábado | I11: FERIADO | L11: =IF(COUNT(J11:K11)=2,K11-J11,0) | M11: =L11*24 | N11: 0 | O11: =N11/60 | P11: =M11-O11 | Q11: =SUMIFS($P:$P,$A:$A,A11,$G:$G,G11) | V11: =IF(COUNT(T11:U11)=2,ROUND((U11-T11)*1440,0),0)
A12: 11111111-1 | B12: Activo | C12: ANA PÉREZ (EJEMPLO) | D12: EXAMEN Y PROCEDIMIENTOS | E12: 46308 | F12: Martes | G12: 46307 | H12: Mañana S/sábado | I12: TRABAJA | J12: 0.33333333 | K12: 0.72916667 | L12: =IF(COUNT(J12:K12)=2,K12-J12,0) | M12: =L12*24 | N12: 60 | O12: =N12/60 | P12: =M12-O12 | Q12: =SUMIFS($P:$P,$A:$A,A12,$G:$G,G12) | R12: 0.44791667 | S12: 0.67708333 | T12: 0.55208333 | U12: 0.59375 | V12: =IF(COUNT(T12:U12)=2,ROUND((U12-T12)*1440,0),0)
A13: 11111111-1 | B13: Activo | C13: ANA PÉREZ (EJEMPLO) | D13: EXAMEN Y PROCEDIMIENTOS | E13: 46309 | F13: Miércoles | G13: 46307 | H13: Mañana S/sábado | I13: TRABAJA | J13: 0.33333333 | K13: 0.72916667 | L13: =IF(COUNT(J13:K13)=2,K13-J13,0) | M13: =L13*24 | N13: 60 | O13: =N13/60 | P13: =M13-O13 | Q13: =SUMIFS($P:$P,$A:$A,A13,$G:$G,G13) | R13: 0.42708333 | S13: 0.64583333 | T13: 0.47916667 | U13: 0.52083333 | V13: =IF(COUNT(T13:U13)=2,ROUND((U13-T13)*1440,0),0)
A14: 11111111-1 | B14: Activo | C14: ANA PÉREZ (EJEMPLO) | D14: EXAMEN Y PROCEDIMIENTOS | E14: 46310 | F14: Jueves | G14: 46307 | H14: Mañana S/sábado | I14: TRABAJA | J14: 0.33333333 | K14: 0.72916667 | L14: =IF(COUNT(J14:K14)=2,K14-J14,0) | M14: =L14*24 | N14: 60 | O14: =N14/60 | P14: =M14-O14 | Q14: =SUMIFS($P:$P,$A:$A,A14,$G:$G,G14) | R14: 0.42708333 | S14: 0.63541667 | T14: 0.47916667 | U14: 0.52083333 | V14: =IF(COUNT(T14:U14)=2,ROUND((U14-T14)*1440,0),0)
A15: 11111111-1 | B15: Activo | C15: ANA PÉREZ (EJEMPLO) | D15: EXAMEN Y PROCEDIMIENTOS | E15: 46311 | F15: Viernes | G15: 46307 | H15: Mañana S/sábado | I15: TRABAJA | J15: 0.33333333 | K15: 0.70833333 | L15: =IF(COUNT(J15:K15)=2,K15-J15,0) | M15: =L15*24 | N15: 60 | O15: =N15/60 | P15: =M15-O15 | Q15: =SUMIFS($P:$P,$A:$A,A15,$G:$G,G15) | R15: 0.44791667 | S15: 0.66666667 | T15: 0.54166667 | U15: 0.58333333 | V15: =IF(COUNT(T15:U15)=2,ROUND((U15-T15)*1440,0),0)
A16: 11111111-1 | B16: Activo | C16: ANA PÉREZ (EJEMPLO) | D16: EXAMEN Y PROCEDIMIENTOS | E16: 46312 | F16: Sábado | G16: 46307 | H16: Mañana S/sábado | I16: LIBRE | L16: =IF(COUNT(J16:K16)=2,K16-J16,0) | M16: =L16*24 | N16: 0 | O16: =N16/60 | P16: =M16-O16 | Q16: =SUMIFS($P:$P,$A:$A,A16,$G:$G,G16) | V16: =IF(COUNT(T16:U16)=2,ROUND((U16-T16)*1440,0),0)
A17: 11111111-1 | B17: Activo | C17: ANA PÉREZ (EJEMPLO) | D17: EXAMEN Y PROCEDIMIENTOS | E17: 46314 | F17: Lunes | G17: 46314 | H17: Mañana C/sábado | I17: TRABAJA | J17: 0.33333333 | K17: 0.6875 | L17: =IF(COUNT(J17:K17)=2,K17-J17,0) | M17: =L17*24 | N17: 60 | O17: =N17/60 | P17: =M17-O17 | Q17: =SUMIFS($P:$P,$A:$A,A17,$G:$G,G17) | R17: 0.41666667 | S17: 0.64583333 | T17: 0.47916667 | U17: 0.52083333 | V17: =IF(COUNT(T17:U17)=2,ROUND((U17-T17)*1440,0),0)
A18: 11111111-1 | B18: Activo | C18: ANA PÉREZ (EJEMPLO) | D18: EXAMEN Y PROCEDIMIENTOS | E18: 46315 | F18: Martes | G18: 46314 | H18: Mañana C/sábado | I18: TRABAJA | J18: 0.33333333 | K18: 0.6875 | L18: =IF(COUNT(J18:K18)=2,K18-J18,0) | M18: =L18*24 | N18: 60 | O18: =N18/60 | P18: =M18-O18 | Q18: =SUMIFS($P:$P,$A:$A,A18,$G:$G,G18) | R18: 0.41666667 | S18: 0.64583333 | T18: 0.47916667 | U18: 0.52083333 | V18: =IF(COUNT(T18:U18)=2,ROUND((U18-T18)*1440,0),0)
A19: 11111111-1 | B19: Activo | C19: ANA PÉREZ (EJEMPLO) | D19: EXAMEN Y PROCEDIMIENTOS | E19: 46316 | F19: Miércoles | G19: 46314 | H19: Mañana C/sábado | I19: TRABAJA | J19: 0.33333333 | K19: 0.6875 | L19: =IF(COUNT(J19:K19)=2,K19-J19,0) | M19: =L19*24 | N19: 60 | O19: =N19/60 | P19: =M19-O19 | Q19: =SUMIFS($P:$P,$A:$A,A19,$G:$G,G19) | R19: 0.44791667 | S19: 0.65625 | T19: 0.53125 | U19: 0.57291667 | V19: =IF(COUNT(T19:U19)=2,ROUND((U19-T19)*1440,0),0)
A20: 11111111-1 | B20: Activo | C20: ANA PÉREZ (EJEMPLO) | D20: EXAMEN Y PROCEDIMIENTOS | E20: 46317 | F20: Jueves | G20: 46314 | H20: Mañana C/sábado | I20: TRABAJA | J20: 0.33333333 | K20: 0.66666667 | L20: =IF(COUNT(J20:K20)=2,K20-J20,0) | M20: =L20*24 | N20: 60 | O20: =N20/60 | P20: =M20-O20 | Q20: =SUMIFS($P:$P,$A:$A,A20,$G:$G,G20) | R20: 0.41666667 | S20: 0.60416667 | T20: 0.46875 | U20: 0.51041667 | V20: =IF(COUNT(T20:U20)=2,ROUND((U20-T20)*1440,0),0)
A21: 11111111-1 | B21: Activo | C21: ANA PÉREZ (EJEMPLO) | D21: EXAMEN Y PROCEDIMIENTOS | E21: 46318 | F21: Viernes | G21: 46314 | H21: Mañana C/sábado | I21: TRABAJA | J21: 0.33333333 | K21: 0.66666667 | L21: =IF(COUNT(J21:K21)=2,K21-J21,0) | M21: =L21*24 | N21: 60 | O21: =N21/60 | P21: =M21-O21 | Q21: =SUMIFS($P:$P,$A:$A,A21,$G:$G,G21) | R21: 0.41666667 | S21: 0.60416667 | T21: 0.46875 | U21: 0.51041667 | V21: =IF(COUNT(T21:U21)=2,ROUND((U21-T21)*1440,0),0)
A22: 11111111-1 | B22: Activo | C22: ANA PÉREZ (EJEMPLO) | D22: EXAMEN Y PROCEDIMIENTOS | E22: 46319 | F22: Sábado | G22: 46314 | H22: Mañana C/sábado | I22: TRABAJA | J22: 0.33333333 | K22: 0.58333333 | L22: =IF(COUNT(J22:K22)=2,K22-J22,0) | M22: =L22*24 | N22: 30 | O22: =N22/60 | P22: =M22-O22 | Q22: =SUMIFS($P:$P,$A:$A,A22,$G:$G,G22) | T22: 0.4375 | U22: 0.45833333 | V22: =IF(COUNT(T22:U22)=2,ROUND((U22-T22)*1440,0),0)
A23: 11111111-1 | B23: Activo | C23: ANA PÉREZ (EJEMPLO) | D23: EXAMEN Y PROCEDIMIENTOS | E23: 46321 | F23: Lunes | G23: 46321 | H23: Intermedio S/sábado | I23: TRABAJA | J23: 0.375 | K23: 0.79166667 | L23: =IF(COUNT(J23:K23)=2,K23-J23,0) | M23: =L23*24 | N23: 60 | O23: =N23/60 | P23: =M23-O23 | Q23: =SUMIFS($P:$P,$A:$A,A23,$G:$G,G23) | R23: 0.45833333 | S23: 0.71875 | T23: 0.5625 | U23: 0.60416667 | V23: =IF(COUNT(T23:U23)=2,ROUND((U23-T23)*1440,0),0)
A24: 11111111-1 | B24: Activo | C24: ANA PÉREZ (EJEMPLO) | D24: EXAMEN Y PROCEDIMIENTOS | E24: 46322 | F24: Martes | G24: 46321 | H24: Intermedio S/sábado | I24: TRABAJA | J24: 0.375 | K24: 0.79166667 | L24: =IF(COUNT(J24:K24)=2,K24-J24,0) | M24: =L24*24 | N24: 60 | O24: =N24/60 | P24: =M24-O24 | Q24: =SUMIFS($P:$P,$A:$A,A24,$G:$G,G24) | R24: 0.45833333 | S24: 0.71875 | T24: 0.5625 | U24: 0.60416667 | V24: =IF(COUNT(T24:U24)=2,ROUND((U24-T24)*1440,0),0)
A25: 11111111-1 | B25: Activo | C25: ANA PÉREZ (EJEMPLO) | D25: EXAMEN Y PROCEDIMIENTOS | E25: 46323 | F25: Miércoles | G25: 46321 | H25: Intermedio S/sábado | I25: TRABAJA | J25: 0.375 | K25: 0.75 | L25: =IF(COUNT(J25:K25)=2,K25-J25,0) | M25: =L25*24 | N25: 60 | O25: =N25/60 | P25: =M25-O25 | Q25: =SUMIFS($P:$P,$A:$A,A25,$G:$G,G25) | R25: 0.45833333 | S25: 0.71875 | T25: 0.59375 | U25: 0.63541667 | V25: =IF(COUNT(T25:U25)=2,ROUND((U25-T25)*1440,0),0)
A26: 11111111-1 | B26: Activo | C26: ANA PÉREZ (EJEMPLO) | D26: EXAMEN Y PROCEDIMIENTOS | E26: 46324 | F26: Jueves | G26: 46321 | H26: Intermedio S/sábado | I26: TRABAJA | J26: 0.375 | K26: 0.75 | L26: =IF(COUNT(J26:K26)=2,K26-J26,0) | M26: =L26*24 | N26: 60 | O26: =N26/60 | P26: =M26-O26 | Q26: =SUMIFS($P:$P,$A:$A,A26,$G:$G,G26) | R26: 0.45833333 | S26: 0.66666667 | T26: 0.54166667 | U26: 0.58333333 | V26: =IF(COUNT(T26:U26)=2,ROUND((U26-T26)*1440,0),0)
A27: 11111111-1 | B27: Activo | C27: ANA PÉREZ (EJEMPLO) | D27: EXAMEN Y PROCEDIMIENTOS | E27: 46325 | F27: Viernes | G27: 46321 | H27: Intermedio S/sábado | I27: TRABAJA | J27: 0.375 | K27: 0.75 | L27: =IF(COUNT(J27:K27)=2,K27-J27,0) | M27: =L27*24 | N27: 60 | O27: =N27/60 | P27: =M27-O27 | Q27: =SUMIFS($P:$P,$A:$A,A27,$G:$G,G27) | R27: 0.45833333 | S27: 0.71875 | T27: 0.59375 | U27: 0.63541667 | V27: =IF(COUNT(T27:U27)=2,ROUND((U27-T27)*1440,0),0)
A28: 11111111-1 | B28: Activo | C28: ANA PÉREZ (EJEMPLO) | D28: EXAMEN Y PROCEDIMIENTOS | E28: 46326 | F28: Sábado | G28: 46321 | H28: Intermedio S/sábado | I28: FERIADO | L28: =IF(COUNT(J28:K28)=2,K28-J28,0) | M28: =L28*24 | N28: 0 | O28: =N28/60 | P28: =M28-O28 | Q28: =SUMIFS($P:$P,$A:$A,A28,$G:$G,G28) | V28: =IF(COUNT(T28:U28)=2,ROUND((U28-T28)*1440,0),0)
A29: 12222222-5 | B29: Activo | C29: BRUNO SOTO (EJEMPLO) | D29: EXAMEN Y PROCEDIMIENTOS | E29: 46296 | F29: Jueves | G29: 46293 | H29: Tarde S/sábado | I29: TRABAJA | J29: 0.4375 | K29: 0.83333333 | L29: =IF(COUNT(J29:K29)=2,K29-J29,0) | M29: =L29*24 | N29: 60 | O29: =N29/60 | P29: =M29-O29 | Q29: =SUMIFS($P:$P,$A:$A,A29,$G:$G,G29) | R29: 0.53125 | S29: 0.77083333 | T29: 0.64583333 | U29: 0.6875 | V29: =IF(COUNT(T29:U29)=2,ROUND((U29-T29)*1440,0),0)
A30: 12222222-5 | B30: Activo | C30: BRUNO SOTO (EJEMPLO) | D30: EXAMEN Y PROCEDIMIENTOS | E30: 46297 | F30: Viernes | G30: 46293 | H30: Tarde S/sábado | I30: TRABAJA | J30: 0.45833333 | K30: 0.83333333 | L30: =IF(COUNT(J30:K30)=2,K30-J30,0) | M30: =L30*24 | N30: 60 | O30: =N30/60 | P30: =M30-O30 | Q30: =SUMIFS($P:$P,$A:$A,A30,$G:$G,G30) | R30: 0.54166667 | S30: 0.78125 | T30: 0.65625 | U30: 0.69791667 | V30: =IF(COUNT(T30:U30)=2,ROUND((U30-T30)*1440,0),0)
A31: 12222222-5 | B31: Activo | C31: BRUNO SOTO (EJEMPLO) | D31: EXAMEN Y PROCEDIMIENTOS | E31: 46298 | F31: Sábado | G31: 46293 | H31: Tarde S/sábado | I31: LIBRE | L31: =IF(COUNT(J31:K31)=2,K31-J31,0) | M31: =L31*24 | N31: 0 | O31: =N31/60 | P31: =M31-O31 | Q31: =SUMIFS($P:$P,$A:$A,A31,$G:$G,G31) | V31: =IF(COUNT(T31:U31)=2,ROUND((U31-T31)*1440,0),0)
A32: 12222222-5 | B32: Activo | C32: BRUNO SOTO (EJEMPLO) | D32: EXAMEN Y PROCEDIMIENTOS | E32: 46300 | F32: Lunes | G32: 46300 | H32: Mañana S/sábado | I32: TRABAJA | J32: 0.33333333 | K32: 0.72916667 | L32: =IF(COUNT(J32:K32)=2,K32-J32,0) | M32: =L32*24 | N32: 60 | O32: =N32/60 | P32: =M32-O32 | Q32: =SUMIFS($P:$P,$A:$A,A32,$G:$G,G32) | R32: 0.42708333 | S32: 0.66666667 | T32: 0.51041667 | U32: 0.55208333 | V32: =IF(COUNT(T32:U32)=2,ROUND((U32-T32)*1440,0),0)
A33: 12222222-5 | B33: Activo | C33: BRUNO SOTO (EJEMPLO) | D33: EXAMEN Y PROCEDIMIENTOS | E33: 46301 | F33: Martes | G33: 46300 | H33: Mañana S/sábado | I33: TRABAJA | J33: 0.33333333 | K33: 0.72916667 | L33: =IF(COUNT(J33:K33)=2,K33-J33,0) | M33: =L33*24 | N33: 60 | O33: =N33/60 | P33: =M33-O33 | Q33: =SUMIFS($P:$P,$A:$A,A33,$G:$G,G33) | R33: 0.42708333 | S33: 0.66666667 | T33: 0.51041667 | U33: 0.55208333 | V33: =IF(COUNT(T33:U33)=2,ROUND((U33-T33)*1440,0),0)
A34: 12222222-5 | B34: Activo | C34: BRUNO SOTO (EJEMPLO) | D34: EXAMEN Y PROCEDIMIENTOS | E34: 46302 | F34: Miércoles | G34: 46300 | H34: Mañana S/sábado | I34: TRABAJA | J34: 0.33333333 | K34: 0.72916667 | L34: =IF(COUNT(J34:K34)=2,K34-J34,0) | M34: =L34*24 | N34: 60 | O34: =N34/60 | P34: =M34-O34 | Q34: =SUMIFS($P:$P,$A:$A,A34,$G:$G,G34) | R34: 0.44791667 | S34: 0.6875 | T34: 0.55208333 | U34: 0.59375 | V34: =IF(COUNT(T34:U34)=2,ROUND((U34-T34)*1440,0),0)
A35: 12222222-5 | B35: Activo | C35: BRUNO SOTO (EJEMPLO) | D35: EXAMEN Y PROCEDIMIENTOS | E35: 46303 | F35: Jueves | G35: 46300 | H35: Mañana S/sábado | I35: TRABAJA | J35: 0.33333333 | K35: 0.72916667 | L35: =IF(COUNT(J35:K35)=2,K35-J35,0) | M35: =L35*24 | N35: 60 | O35: =N35/60 | P35: =M35-O35 | Q35: =SUMIFS($P:$P,$A:$A,A35,$G:$G,G35) | R35: 0.44791667 | S35: 0.69791667 | T35: 0.5625 | U35: 0.60416667 | V35: =IF(COUNT(T35:U35)=2,ROUND((U35-T35)*1440,0),0)
A36: 12222222-5 | B36: Activo | C36: BRUNO SOTO (EJEMPLO) | D36: EXAMEN Y PROCEDIMIENTOS | E36: 46304 | F36: Viernes | G36: 46300 | H36: Mañana S/sábado | I36: TRABAJA | J36: 0.33333333 | K36: 0.70833333 | L36: =IF(COUNT(J36:K36)=2,K36-J36,0) | M36: =L36*24 | N36: 60 | O36: =N36/60 | P36: =M36-O36 | Q36: =SUMIFS($P:$P,$A:$A,A36,$G:$G,G36) | R36: 0.42708333 | S36: 0.67708333 | T36: 0.55208333 | U36: 0.59375 | V36: =IF(COUNT(T36:U36)=2,ROUND((U36-T36)*1440,0),0)
A37: 12222222-5 | B37: Activo | C37: BRUNO SOTO (EJEMPLO) | D37: EXAMEN Y PROCEDIMIENTOS | E37: 46305 | F37: Sábado | G37: 46300 | H37: Mañana S/sábado | I37: LIBRE | L37: =IF(COUNT(J37:K37)=2,K37-J37,0) | M37: =L37*24 | N37: 0 | O37: =N37/60 | P37: =M37-O37 | Q37: =SUMIFS($P:$P,$A:$A,A37,$G:$G,G37) | V37: =IF(COUNT(T37:U37)=2,ROUND((U37-T37)*1440,0),0)
A38: 12222222-5 | B38: Activo | C38: BRUNO SOTO (EJEMPLO) | D38: EXAMEN Y PROCEDIMIENTOS | E38: 46307 | F38: Lunes | G38: 46307 | H38: Mañana C/sábado | I38: FERIADO | L38: =IF(COUNT(J38:K38)=2,K38-J38,0) | M38: =L38*24 | N38: 0 | O38: =N38/60 | P38: =M38-O38 | Q38: =SUMIFS($P:$P,$A:$A,A38,$G:$G,G38) | V38: =IF(COUNT(T38:U38)=2,ROUND((U38-T38)*1440,0),0)
A39: 12222222-5 | B39: Activo | C39: BRUNO SOTO (EJEMPLO) | D39: EXAMEN Y PROCEDIMIENTOS | E39: 46308 | F39: Martes | G39: 46307 | H39: Mañana C/sábado | I39: TRABAJA | J39: 0.33333333 | K39: 0.6875 | L39: =IF(COUNT(J39:K39)=2,K39-J39,0) | M39: =L39*24 | N39: 60 | O39: =N39/60 | P39: =M39-O39 | Q39: =SUMIFS($P:$P,$A:$A,A39,$G:$G,G39) | R39: 0.41666667 | S39: 0.59375 | T39: 0.46875 | U39: 0.51041667 | V39: =IF(COUNT(T39:U39)=2,ROUND((U39-T39)*1440,0),0)
A40: 12222222-5 | B40: Activo | C40: BRUNO SOTO (EJEMPLO) | D40: EXAMEN Y PROCEDIMIENTOS | E40: 46309 | F40: Miércoles | G40: 46307 | H40: Mañana C/sábado | I40: TRABAJA | J40: 0.33333333 | K40: 0.6875 | L40: =IF(COUNT(J40:K40)=2,K40-J40,0) | M40: =L40*24 | N40: 60 | O40: =N40/60 | P40: =M40-O40 | Q40: =SUMIFS($P:$P,$A:$A,A40,$G:$G,G40) | R40: 0.41666667 | S40: 0.625 | T40: 0.46875 | U40: 0.51041667 | V40: =IF(COUNT(T40:U40)=2,ROUND((U40-T40)*1440,0),0)
...

Sheet RESUMEN_EJECUTIVOS
A1: RUT | B1: NOMBRE | C1: SERVICIO | D1: HORAS CONTRATO SEMANAL | E1: MÁX. HORAS SEMANA | F1: HORAS PLANIFICADAS MES | G1: HORAS CONTRATO MES (ref.) | H1: DIFERENCIA | I1: DÍAS TRABAJADOS | J1: SÁBADOS TRABAJADOS | K1: SEMANAS TARDE | L1: DÍAS LIBRE | M1: LICENCIA | N1: VACACIONES
A2: 11111111-1 | B2: ANA PÉREZ (EJEMPLO) | C2: EXAMEN Y PROCEDIMIENTOS | D2: 42 | E2: 42 | F2: =SUMIFS(PLANIFICACION_MENSUAL!$P:$P,PLANIFICACION_MENSUAL!$A:$A,A2) | G2: =D2/5*21 | H2: =F2-G2 | I2: =COUNTIFS(PLANIFICACION_MENSUAL!$A:$A,A2,PLANIFICACION_MENSUAL!$I:$I,"TRABAJA") | J2: =COUNTIFS(PLANIFICACION_MENSUAL!$A:$A,A2,PLANIFICACION_MENSUAL!$F:$F,"Sábado",PLANIFICACION_MENSUAL!$I:$I,"TRABAJA") | K2: 1 | L2: =COUNTIFS(PLANIFICACION_MENSUAL!$A:$A,A2,PLANIFICACION_MENSUAL!$I:$I,"LIBRE") | M2: =COUNTIFS(PLANIFICACION_MENSUAL!$A:$A,A2,PLANIFICACION_MENSUAL!$I:$I,"LICENCIA") | N2: =COUNTIFS(PLANIFICACION_MENSUAL!$A:$A,A2,PLANIFICACION_MENSUAL!$I:$I,"VACACIONES")
A3: 12222222-5 | B3: BRUNO SOTO (EJEMPLO) | C3: EXAMEN Y PROCEDIMIENTOS | D3: 42 | E3: 42 | F3: =SUMIFS(PLANIFICACION_MENSUAL!$P:$P,PLANIFICACION_MENSUAL!$A:$A,A3) | G3: =D3/5*21 | H3: =F3-G3 | I3: =COUNTIFS(PLANIFICACION_MENSUAL!$A:$A,A3,PLANIFICACION_MENSUAL!$I:$I,"TRABAJA") | J3: =COUNTIFS(PLANIFICACION_MENSUAL!$A:$A,A3,PLANIFICACION_MENSUAL!$F:$F,"Sábado",PLANIFICACION_MENSUAL!$I:$I,"TRABAJA") | K3: 1 | L3: =COUNTIFS(PLANIFICACION_MENSUAL!$A:$A,A3,PLANIFICACION_MENSUAL!$I:$I,"LIBRE") | M3: =COUNTIFS(PLANIFICACION_MENSUAL!$A:$A,A3,PLANIFICACION_MENSUAL!$I:$I,"LICENCIA") | N3: =COUNTIFS(PLANIFICACION_MENSUAL!$A:$A,A3,PLANIFICACION_MENSUAL!$I:$I,"VACACIONES")
A4: 13333333-9 | B4: CARLA DÍAZ (EJEMPLO) | C4: EXAMEN Y PROCEDIMIENTOS | D4: 42 | E4: 42 | F4: =SUMIFS(PLANIFICACION_MENSUAL!$P:$P,PLANIFICACION_MENSUAL!$A:$A,A4) | G4: =D4/5*21 | H4: =F4-G4 | I4: =COUNTIFS(PLANIFICACION_MENSUAL!$A:$A,A4,PLANIFICACION_MENSUAL!$I:$I,"TRABAJA") | J4: =COUNTIFS(PLANIFICACION_MENSUAL!$A:$A,A4,PLANIFICACION_MENSUAL!$F:$F,"Sábado",PLANIFICACION_MENSUAL!$I:$I,"TRABAJA") | K4: 1 | L4: =COUNTIFS(PLANIFICACION_MENSUAL!$A:$A,A4,PLANIFICACION_MENSUAL!$I:$I,"LIBRE") | M4: =COUNTIFS(PLANIFICACION_MENSUAL!$A:$A,A4,PLANIFICACION_MENSUAL!$I:$I,"LICENCIA") | N4: =COUNTIFS(PLANIFICACION_MENSUAL!$A:$A,A4,PLANIFICACION_MENSUAL!$I:$I,"VACACIONES")
A5: 14444444-2 | B5: DIEGO ROJAS (EJEMPLO) | C5: EXAMEN Y PROCEDIMIENTOS | D5: 42 | E5: 42 | F5: =SUMIFS(PLANIFICACION_MENSUAL!$P:$P,PLANIFICACION_MENSUAL!$A:$A,A5) | G5: =D5/5*21 | H5: =F5-G5 | I5: =COUNTIFS(PLANIFICACION_MENSUAL!$A:$A,A5,PLANIFICACION_MENSUAL!$I:$I,"TRABAJA") | J5: =COUNTIFS(PLANIFICACION_MENSUAL!$A:$A,A5,PLANIFICACION_MENSUAL!$F:$F,"Sábado",PLANIFICACION_MENSUAL!$I:$I,"TRABAJA") | K5: 1 | L5: =COUNTIFS(PLANIFICACION_MENSUAL!$A:$A,A5,PLANIFICACION_MENSUAL!$I:$I,"LIBRE") | M5: =COUNTIFS(PLANIFICACION_MENSUAL!$A:$A,A5,PLANIFICACION_MENSUAL!$I:$I,"LICENCIA") | N5: =COUNTIFS(PLANIFICACION_MENSUAL!$A:$A,A5,PLANIFICACION_MENSUAL!$I:$I,"VACACIONES")
A6: 15555555-6 | B6: ELENA MUÑOZ (EJEMPLO) | C6: EXAMEN Y PROCEDIMIENTOS | D6: 42 | E6: 42 | F6: =SUMIFS(PLANIFICACION_MENSUAL!$P:$P,PLANIFICACION_MENSUAL!$A:$A,A6) | G6: =D6/5*21 | H6: =F6-G6 | I6: =COUNTIFS(PLANIFICACION_MENSUAL!$A:$A,A6,PLANIFICACION_MENSUAL!$I:$I,"TRABAJA") | J6: =COUNTIFS(PLANIFICACION_MENSUAL!$A:$A,A6,PLANIFICACION_MENSUAL!$F:$F,"Sábado",PLANIFICACION_MENSUAL!$I:$I,"TRABAJA") | K6: 1 | L6: =COUNTIFS(PLANIFICACION_MENSUAL!$A:$A,A6,PLANIFICACION_MENSUAL!$I:$I,"LIBRE") | M6: =COUNTIFS(PLANIFICACION_MENSUAL!$A:$A,A6,PLANIFICACION_MENSUAL!$I:$I,"LICENCIA") | N6: =COUNTIFS(PLANIFICACION_MENSUAL!$A:$A,A6,PLANIFICACION_MENSUAL!$I:$I,"VACACIONES")
A7: 16666666-K | B7: FELIPE VERA (EJEMPLO) | C7: EXAMEN Y PROCEDIMIENTOS | D7: 42 | E7: 42 | F7: =SUMIFS(PLANIFICACION_MENSUAL!$P:$P,PLANIFICACION_MENSUAL!$A:$A,A7) | G7: =D7/5*21 | H7: =F7-G7 | I7: =COUNTIFS(PLANIFICACION_MENSUAL!$A:$A,A7,PLANIFICACION_MENSUAL!$I:$I,"TRABAJA") | J7: =COUNTIFS(PLANIFICACION_MENSUAL!$A:$A,A7,PLANIFICACION_MENSUAL!$F:$F,"Sábado",PLANIFICACION_MENSUAL!$I:$I,"TRABAJA") | K7: 1 | L7: =COUNTIFS(PLANIFICACION_MENSUAL!$A:$A,A7,PLANIFICACION_MENSUAL!$I:$I,"LIBRE") | M7: =COUNTIFS(PLANIFICACION_MENSUAL!$A:$A,A7,PLANIFICACION_MENSUAL!$I:$I,"LICENCIA") | N7: =COUNTIFS(PLANIFICACION_MENSUAL!$A:$A,A7,PLANIFICACION_MENSUAL!$I:$I,"VACACIONES")
A8: 17777777-3 | B8: GABRIELA LAGOS (EJEMPLO) | C8: EXAMEN Y PROCEDIMIENTOS | D8: 42 | E8: 42 | F8: =SUMIFS(PLANIFICACION_MENSUAL!$P:$P,PLANIFICACION_MENSUAL!$A:$A,A8) | G8: =D8/5*21 | H8: =F8-G8 | I8: =COUNTIFS(PLANIFICACION_MENSUAL!$A:$A,A8,PLANIFICACION_MENSUAL!$I:$I,"TRABAJA") | J8: =COUNTIFS(PLANIFICACION_MENSUAL!$A:$A,A8,PLANIFICACION_MENSUAL!$F:$F,"Sábado",PLANIFICACION_MENSUAL!$I:$I,"TRABAJA") | K8: 1 | L8: =COUNTIFS(PLANIFICACION_MENSUAL!$A:$A,A8,PLANIFICACION_MENSUAL!$I:$I,"LIBRE") | M8: =COUNTIFS(PLANIFICACION_MENSUAL!$A:$A,A8,PLANIFICACION_MENSUAL!$I:$I,"LICENCIA") | N8: =COUNTIFS(PLANIFICACION_MENSUAL!$A:$A,A8,PLANIFICACION_MENSUAL!$I:$I,"VACACIONES")
A9: 18888888-7 | B9: HUGO FUENTES (EJEMPLO) | C9: EXAMEN Y PROCEDIMIENTOS | D9: 42 | E9: 42 | F9: =SUMIFS(PLANIFICACION_MENSUAL!$P:$P,PLANIFICACION_MENSUAL!$A:$A,A9) | G9: =D9/5*21 | H9: =F9-G9 | I9: =COUNTIFS(PLANIFICACION_MENSUAL!$A:$A,A9,PLANIFICACION_MENSUAL!$I:$I,"TRABAJA") | J9: =COUNTIFS(PLANIFICACION_MENSUAL!$A:$A,A9,PLANIFICACION_MENSUAL!$F:$F,"Sábado",PLANIFICACION_MENSUAL!$I:$I,"TRABAJA") | K9: 1 | L9: =COUNTIFS(PLANIFICACION_MENSUAL!$A:$A,A9,PLANIFICACION_MENSUAL!$I:$I,"LIBRE") | M9: =COUNTIFS(PLANIFICACION_MENSUAL!$A:$A,A9,PLANIFICACION_MENSUAL!$I:$I,"LICENCIA") | N9: =COUNTIFS(PLANIFICACION_MENSUAL!$A:$A,A9,PLANIFICACION_MENSUAL!$I:$I,"VACACIONES")
A10: 19999999-0 | B10: ISABEL CASTRO (EJEMPLO) | C10: EXAMEN Y PROCEDIMIENTOS | D10: 42 | E10: 42 | F10: =SUMIFS(PLANIFICACION_MENSUAL!$P:$P,PLANIFICACION_MENSUAL!$A:$A,A10) | G10: =D10/5*21 | H10: =F10-G10 | I10: =COUNTIFS(PLANIFICACION_MENSUAL!$A:$A,A10,PLANIFICACION_MENSUAL!$I:$I,"TRABAJA") | J10: =COUNTIFS(PLANIFICACION_MENSUAL!$A:$A,A10,PLANIFICACION_MENSUAL!$F:$F,"Sábado",PLANIFICACION_MENSUAL!$I:$I,"TRABAJA") | K10: 1 | L10: =COUNTIFS(PLANIFICACION_MENSUAL!$A:$A,A10,PLANIFICACION_MENSUAL!$I:$I,"LIBRE") | M10: =COUNTIFS(PLANIFICACION_MENSUAL!$A:$A,A10,PLANIFICACION_MENSUAL!$I:$I,"LICENCIA") | N10: =COUNTIFS(PLANIFICACION_MENSUAL!$A:$A,A10,PLANIFICACION_MENSUAL!$I:$I,"VACACIONES")
A11: 21111110-0 | B11: JORGE REYES (EJEMPLO) | C11: EXAMEN Y PROCEDIMIENTOS | D11: 42 | E11: 42 | F11: =SUMIFS(PLANIFICACION_MENSUAL!$P:$P,PLANIFICACION_MENSUAL!$A:$A,A11) | G11: =D11/5*21 | H11: =F11-G11 | I11: =COUNTIFS(PLANIFICACION_MENSUAL!$A:$A,A11,PLANIFICACION_MENSUAL!$I:$I,"TRABAJA") | J11: =COUNTIFS(PLANIFICACION_MENSUAL!$A:$A,A11,PLANIFICACION_MENSUAL!$F:$F,"Sábado",PLANIFICACION_MENSUAL!$I:$I,"TRABAJA") | K11: 1 | L11: =COUNTIFS(PLANIFICACION_MENSUAL!$A:$A,A11,PLANIFICACION_MENSUAL!$I:$I,"LIBRE") | M11: =COUNTIFS(PLANIFICACION_MENSUAL!$A:$A,A11,PLANIFICACION_MENSUAL!$I:$I,"LICENCIA") | N11: =COUNTIFS(PLANIFICACION_MENSUAL!$A:$A,A11,PLANIFICACION_MENSUAL!$I:$I,"VACACIONES")
A12: 22222221-4 | B12: KAREN SILVA (EJEMPLO) | C12: EXAMEN Y PROCEDIMIENTOS | D12: 42 | E12: 42 | F12: =SUMIFS(PLANIFICACION_MENSUAL!$P:$P,PLANIFICACION_MENSUAL!$A:$A,A12) | G12: =D12/5*21 | H12: =F12-G12 | I12: =COUNTIFS(PLANIFICACION_MENSUAL!$A:$A,A12,PLANIFICACION_MENSUAL!$I:$I,"TRABAJA") | J12: =COUNTIFS(PLANIFICACION_MENSUAL!$A:$A,A12,PLANIFICACION_MENSUAL!$F:$F,"Sábado",PLANIFICACION_MENSUAL!$I:$I,"TRABAJA") | K12: 1 | L12: =COUNTIFS(PLANIFICACION_MENSUAL!$A:$A,A12,PLANIFICACION_MENSUAL!$I:$I,"LIBRE") | M12: =COUNTIFS(PLANIFICACION_MENSUAL!$A:$A,A12,PLANIFICACION_MENSUAL!$I:$I,"LICENCIA") | N12: =COUNTIFS(PLANIFICACION_MENSUAL!$A:$A,A12,PLANIFICACION_MENSUAL!$I:$I,"VACACIONES")
A13: 23333332-8 | B13: LUIS MORALES (EJEMPLO) | C13: EXAMEN Y PROCEDIMIENTOS | D13: 42 | E13: 42 | F13: =SUMIFS(PLANIFICACION_MENSUAL!$P:$P,PLANIFICACION_MENSUAL!$A:$A,A13) | G13: =D13/5*21 | H13: =F13-G13 | I13: =COUNTIFS(PLANIFICACION_MENSUAL!$A:$A,A13,PLANIFICACION_MENSUAL!$I:$I,"TRABAJA") | J13: =COUNTIFS(PLANIFICACION_MENSUAL!$A:$A,A13,PLANIFICACION_MENSUAL!$F:$F,"Sábado",PLANIFICACION_MENSUAL!$I:$I,"TRABAJA") | K13: 1 | L13: =COUNTIFS(PLANIFICACION_MENSUAL!$A:$A,A13,PLANIFICACION_MENSUAL!$I:$I,"LIBRE") | M13: =COUNTIFS(PLANIFICACION_MENSUAL!$A:$A,A13,PLANIFICACION_MENSUAL!$I:$I,"LICENCIA") | N13: =COUNTIFS(PLANIFICACION_MENSUAL!$A:$A,A13,PLANIFICACION_MENSUAL!$I:$I,"VACACIONES")
... A17: 27777776-2 | B17: PABLO HERRERA (EJEMPLO) | C17: IMAGENES | D17: 42 | E17: 42 | F17: =SUMIFS(PLANIFICACION_MENSUAL!$P:$P,PLANIFICACION_MENSUAL!$A:$A,A17) | G17: =D17/5*21 | H17: =F17-G17 | I17: =COUNTIFS(PLANIFICACION_MENSUAL!$A:$A,A17,PLANIFICACION_MENSUAL!$I:$I,"TRABAJA") | J17: =COUNTIFS(PLANIFICACION_MENSUAL!$A:$A,A17,PLANIFICACION_MENSUAL!$F:$F,"Sábado",PLANIFICACION_MENSUAL!$I:$I,"TRABAJA") | K17: 0 | L17: =COUNTIFS(PLANIFICACION_MENSUAL!$A:$A,A17,PLANIFICACION_MENSUAL!$I:$I,"LIBRE") | M17: =COUNTIFS(PLANIFICACION_MENSUAL!$A:$A,A17,PLANIFICACION_MENSUAL!$I:$I,"LICENCIA") | N17: =COUNTIFS(PLANIFICACION_MENSUAL!$A:$A,A17,PLANIFICACION_MENSUAL!$I:$I,"VACACIONES")
A18: TOTAL | B18: =COUNTA(A2:A17)&" ejecutivos" | D18: =SUM(D2:D17) | E18: =MAX(E2:E17) | F18: =SUM(F2:F17) | G18: =SUM(G2:G17) | H18: =SUM(H2:H17) | I18: =SUM(I2:I17) | J18: =SUM(J2:J17) | K18: =SUM(K2:K17) | L18: =SUM(L2:L17) | M18: =SUM(M2:M17) | N18: =SUM(N2:N17)

Sheet MATRIZ_COBERTURA
A1: FECHA | B1: DIA | C1: TIPO_DIA | D1: 0.33333333 | E1: 0.375 | F1: 0.41666667 | G1: 0.45833333 | H1: 0.5 | I1: 0.54166667 | J1: 0.58333333 | K1: 0.625 | L1: 0.66666667 | M1: 0.70833333 | N1: 0.75 | O1: 0.79166667 | P1: TURNOS DEL DÍA
A2: 46296 | B2: Jueves | C2: HÁBIL | D2: =COUNTIFS(PLANIFICACION_MENSUAL!$E$2:$E$433,$A2,PLANIFICACION_MENSUAL!$J$2:$J$433,"<="&(D$1+0.0001),PLANIFICACION_MENSUAL!$K$2:$K$433,">"&(D$1+0.0001)) | E2: =COUNTIFS(PLANIFICACION_MENSUAL!$E$2:$E$433,$A2,PLANIFICACION_MENSUAL!$J$2:$J$433,"<="&(E$1+0.0001),PLANIFICACION_MENSUAL!$K$2:$K$433,">"&(E$1+0.0001)) | F2: =COUNTIFS(PLANIFICACION_MENSUAL!$E$2:$E$433,$A2,PLANIFICACION_MENSUAL!$J$2:$J$433,"<="&(F$1+0.0001),PLANIFICACION_MENSUAL!$K$2:$K$433,">"&(F$1+0.0001)) | G2: =COUNTIFS(PLANIFICACION_MENSUAL!$E$2:$E$433,$A2,PLANIFICACION_MENSUAL!$J$2:$J$433,"<="&(G$1+0.0001),PLANIFICACION_MENSUAL!$K$2:$K$433,">"&(G$1+0.0001)) | H2: =COUNTIFS(PLANIFICACION_MENSUAL!$E$2:$E$433,$A2,PLANIFICACION_MENSUAL!$J$2:$J$433,"<="&(H$1+0.0001),PLANIFICACION_MENSUAL!$K$2:$K$433,">"&(H$1+0.0001)) | I2: =COUNTIFS(PLANIFICACION_MENSUAL!$E$2:$E$433,$A2,PLANIFICACION_MENSUAL!$J$2:$J$433,"<="&(I$1+0.0001),PLANIFICACION_MENSUAL!$K$2:$K$433,">"&(I$1+0.0001)) | J2: =COUNTIFS(PLANIFICACION_MENSUAL!$E$2:$E$433,$A2,PLANIFICACION_MENSUAL!$J$2:$J$433,"<="&(J$1+0.0001),PLANIFICACION_MENSUAL!$K$2:$K$433,">"&(J$1+0.0001)) | K2: =COUNTIFS(PLANIFICACION_MENSUAL!$E$2:$E$433,$A2,PLANIFICACION_MENSUAL!$J$2:$J$433,"<="&(K$1+0.0001),PLANIFICACION_MENSUAL!$K$2:$K$433,">"&(K$1+0.0001)) | ... O2: =COUNTIFS(PLANIFICACION_MENSUAL!$E$2:$E$433,$A2,PLANIFICACION_MENSUAL!$J$2:$J$433,"<="&(O$1+0.0001),PLANIFICACION_MENSUAL!$K$2:$K$433,">"&(O$1+0.0001)) | P2: =COUNTIFS(PLANIFICACION_MENSUAL!$E$2:$E$433,$A2,PLANIFICACION_MENSUAL!$I$2:$I$433,"TRABAJA")
A3: 46297 | B3: Viernes | C3: HÁBIL | D3: =COUNTIFS(PLANIFICACION_MENSUAL!$E$2:$E$433,$A3,PLANIFICACION_MENSUAL!$J$2:$J$433,"<="&(D$1+0.0001),PLANIFICACION_MENSUAL!$K$2:$K$433,">"&(D$1+0.0001)) | E3: =COUNTIFS(PLANIFICACION_MENSUAL!$E$2:$E$433,$A3,PLANIFICACION_MENSUAL!$J$2:$J$433,"<="&(E$1+0.0001),PLANIFICACION_MENSUAL!$K$2:$K$433,">"&(E$1+0.0001)) | F3: =COUNTIFS(PLANIFICACION_MENSUAL!$E$2:$E$433,$A3,PLANIFICACION_MENSUAL!$J$2:$J$433,"<="&(F$1+0.0001),PLANIFICACION_MENSUAL!$K$2:$K$433,">"&(F$1+0.0001)) | G3: =COUNTIFS(PLANIFICACION_MENSUAL!$E$2:$E$433,$A3,PLANIFICACION_MENSUAL!$J$2:$J$433,"<="&(G$1+0.0001),PLANIFICACION_MENSUAL!$K$2:$K$433,">"&(G$1+0.0001)) | H3: =COUNTIFS(PLANIFICACION_MENSUAL!$E$2:$E$433,$A3,PLANIFICACION_MENSUAL!$J$2:$J$433,"<="&(H$1+0.0001),PLANIFICACION_MENSUAL!$K$2:$K$433,">"&(H$1+0.0001)) | I3: =COUNTIFS(PLANIFICACION_MENSUAL!$E$2:$E$433,$A3,PLANIFICACION_MENSUAL!$J$2:$J$433,"<="&(I$1+0.0001),PLANIFICACION_MENSUAL!$K$2:$K$433,">"&(I$1+0.0001)) | J3: =COUNTIFS(PLANIFICACION_MENSUAL!$E$2:$E$433,$A3,PLANIFICACION_MENSUAL!$J$2:$J$433,"<="&(J$1+0.0001),PLANIFICACION_MENSUAL!$K$2:$K$433,">"&(J$1+0.0001)) | K3: =COUNTIFS(PLANIFICACION_MENSUAL!$E$2:$E$433,$A3,PLANIFICACION_MENSUAL!$J$2:$J$433,"<="&(K$1+0.0001),PLANIFICACION_MENSUAL!$K$2:$K$433,">"&(K$1+0.0001)) | ... O3: =COUNTIFS(PLANIFICACION_MENSUAL!$E$2:$E$433,$A3,PLANIFICACION_MENSUAL!$J$2:$J$433,"<="&(O$1+0.0001),PLANIFICACION_MENSUAL!$K$2:$K$433,">"&(O$1+0.0001)) | P3: =COUNTIFS(PLANIFICACION_MENSUAL!$E$2:$E$433,$A3,PLANIFICACION_MENSUAL!$I$2:$I$433,"TRABAJA")
A4: 46298 | B4: Sábado | C4: SÁBADO | D4: =COUNTIFS(PLANIFICACION_MENSUAL!$E$2:$E$433,$A4,PLANIFICACION_MENSUAL!$J$2:$J$433,"<="&(D$1+0.0001),PLANIFICACION_MENSUAL!$K$2:$K$433,">"&(D$1+0.0001)) | E4: =COUNTIFS(PLANIFICACION_MENSUAL!$E$2:$E$433,$A4,PLANIFICACION_MENSUAL!$J$2:$J$433,"<="&(E$1+0.0001),PLANIFICACION_MENSUAL!$K$2:$K$433,">"&(E$1+0.0001)) | F4: =COUNTIFS(PLANIFICACION_MENSUAL!$E$2:$E$433,$A4,PLANIFICACION_MENSUAL!$J$2:$J$433,"<="&(F$1+0.0001),PLANIFICACION_MENSUAL!$K$2:$K$433,">"&(F$1+0.0001)) | G4: =COUNTIFS(PLANIFICACION_MENSUAL!$E$2:$E$433,$A4,PLANIFICACION_MENSUAL!$J$2:$J$433,"<="&(G$1+0.0001),PLANIFICACION_MENSUAL!$K$2:$K$433,">"&(G$1+0.0001)) | H4: =COUNTIFS(PLANIFICACION_MENSUAL!$E$2:$E$433,$A4,PLANIFICACION_MENSUAL!$J$2:$J$433,"<="&(H$1+0.0001),PLANIFICACION_MENSUAL!$K$2:$K$433,">"&(H$1+0.0001)) | I4: =COUNTIFS(PLANIFICACION_MENSUAL!$E$2:$E$433,$A4,PLANIFICACION_MENSUAL!$J$2:$J$433,"<="&(I$1+0.0001),PLANIFICACION_MENSUAL!$K$2:$K$433,">"&(I$1+0.0001)) | J4: =COUNTIFS(PLANIFICACION_MENSUAL!$E$2:$E$433,$A4,PLANIFICACION_MENSUAL!$J$2:$J$433,"<="&(J$1+0.0001),PLANIFICACION_MENSUAL!$K$2:$K$433,">"&(J$1+0.0001)) | K4: =COUNTIFS(PLANIFICACION_MENSUAL!$E$2:$E$433,$A4,PLANIFICACION_MENSUAL!$J$2:$J$433,"<="&(K$1+0.0001),PLANIFICACION_MENSUAL!$K$2:$K$433,">"&(K$1+0.0001)) | ... O4: =COUNTIFS(PLANIFICACION_MENSUAL!$E$2:$E$433,$A4,PLANIFICACION_MENSUAL!$J$2:$J$433,"<="&(O$1+0.0001),PLANIFICACION_MENSUAL!$K$2:$K$433,">"&(O$1+0.0001)) | P4: =COUNTIFS(PLANIFICACION_MENSUAL!$E$2:$E$433,$A4,PLANIFICACION_MENSUAL!$I$2:$I$433,"TRABAJA")
A5: 46300 | B5: Lunes | C5: HÁBIL | D5: =COUNTIFS(PLANIFICACION_MENSUAL!$E$2:$E$433,$A5,PLANIFICACION_MENSUAL!$J$2:$J$433,"<="&(D$1+0.0001),PLANIFICACION_MENSUAL!$K$2:$K$433,">"&(D$1+0.0001)) | E5: =COUNTIFS(PLANIFICACION_MENSUAL!$E$2:$E$433,$A5,PLANIFICACION_MENSUAL!$J$2:$J$433,"<="&(E$1+0.0001),PLANIFICACION_MENSUAL!$K$2:$K$433,">"&(E$1+0.0001)) | F5: =COUNTIFS(PLANIFICACION_MENSUAL!$E$2:$E$433,$A5,PLANIFICACION_MENSUAL!$J$2:$J$433,"<="&(F$1+0.0001),PLANIFICACION_MENSUAL!$K$2:$K$433,">"&(F$1+0.0001)) | G5: =COUNTIFS(PLANIFICACION_MENSUAL!$E$2:$E$433,$A5,PLANIFICACION_MENSUAL!$J$2:$J$433,"<="&(G$1+0.0001),PLANIFICACION_MENSUAL!$K$2:$K$433,">"&(G$1+0.0001)) | H5: =COUNTIFS(PLANIFICACION_MENSUAL!$E$2:$E$433,$A5,PLANIFICACION_MENSUAL!$J$2:$J$433,"<="&(H$1+0.0001),PLANIFICACION_MENSUAL!$K$2:$K$433,">"&(H$1+0.0001)) | I5: =COUNTIFS(PLANIFICACION_MENSUAL!$E$2:$E$433,$A5,PLANIFICACION_MENSUAL!$J$2:$J$433,"<="&(I$1+0.0001),PLANIFICACION_MENSUAL!$K$2:$K$433,">"&(I$1+0.0001)) | J5: =COUNTIFS(PLANIFICACION_MENSUAL!$E$2:$E$433,$A5,PLANIFICACION_MENSUAL!$J$2:$J$433,"<="&(J$1+0.0001),PLANIFICACION_MENSUAL!$K$2:$K$433,">"&(J$1+0.0001)) | K5: =COUNTIFS(PLANIFICACION_MENSUAL!$E$2:$E$433,$A5,PLANIFICACION_MENSUAL!$J$2:$J$433,"<="&(K$1+0.0001),PLANIFICACION_MENSUAL!$K$2:$K$433,">"&(K$1+0.0001)) | ... O5: =COUNTIFS(PLANIFICACION_MENSUAL!$E$2:$E$433,$A5,PLANIFICACION_MENSUAL!$J$2:$J$433,"<="&(O$1+0.0001),PLANIFICACION_MENSUAL!$K$2:$K$433,">"&(O$1+0.0001)) | P5: =COUNTIFS(PLANIFICACION_MENSUAL!$E$2:$E$433,$A5,PLANIFICACION_MENSUAL!$I$2:$I$433,"TRABAJA")
A6: 46301 | B6: Martes | C6: HÁBIL | D6: =COUNTIFS(PLANIFICACION_MENSUAL!$E$2:$E$433,$A6,PLANIFICACION_MENSUAL!$J$2:$J$433,"<="&(D$1+0.0001),PLANIFICACION_MENSUAL!$K$2:$K$433,">"&(D$1+0.0001)) | E6: =COUNTIFS(PLANIFICACION_MENSUAL!$E$2:$E$433,$A6,PLANIFICACION_MENSUAL!$J$2:$J$433,"<="&(E$1+0.0001),PLANIFICACION_MENSUAL!$K$2:$K$433,">"&(E$1+0.0001)) | F6: =COUNTIFS(PLANIFICACION_MENSUAL!$E$2:$E$433,$A6,PLANIFICACION_MENSUAL!$J$2:$J$433,"<="&(F$1+0.0001),PLANIFICACION_MENSUAL!$K$2:$K$433,">"&(F$1+0.0001)) | G6: =COUNTIFS(PLANIFICACION_MENSUAL!$E$2:$E$433,$A6,PLANIFICACION_MENSUAL!$J$2:$J$433,"<="&(G$1+0.0001),PLANIFICACION_MENSUAL!$K$2:$K$433,">"&(G$1+0.0001)) | H6: =COUNTIFS(PLANIFICACION_MENSUAL!$E$2:$E$433,$A6,PLANIFICACION_MENSUAL!$J$2:$J$433,"<="&(H$1+0.0001),PLANIFICACION_MENSUAL!$K$2:$K$433,">"&(H$1+0.0001)) | I6: =COUNTIFS(PLANIFICACION_MENSUAL!$E$2:$E$433,$A6,PLANIFICACION_MENSUAL!$J$2:$J$433,"<="&(I$1+0.0001),PLANIFICACION_MENSUAL!$K$2:$K$433,">"&(I$1+0.0001)) | J6: =COUNTIFS(PLANIFICACION_MENSUAL!$E$2:$E$433,$A6,PLANIFICACION_MENSUAL!$J$2:$J$433,"<="&(J$1+0.0001),PLANIFICACION_MENSUAL!$K$2:$K$433,">"&(J$1+0.0001)) | K6: =COUNTIFS(PLANIFICACION_MENSUAL!$E$2:$E$433,$A6,PLANIFICACION_MENSUAL!$J$2:$J$433,"<="&(K$1+0.0001),PLANIFICACION_MENSUAL!$K$2:$K$433,">"&(K$1+0.0001)) | ... O6: =COUNTIFS(PLANIFICACION_MENSUAL!$E$2:$E$433,$A6,PLANIFICACION_MENSUAL!$J$2:$J$433,"<="&(O$1+0.0001),PLANIFICACION_MENSUAL!$K$2:$K$433,">"&(O$1+0.0001)) | P6: =COUNTIFS(PLANIFICACION_MENSUAL!$E$2:$E$433,$A6,PLANIFICACION_MENSUAL!$I$2:$I$433,"TRABAJA")
A7: 46302 | B7: Miércoles | C7: HÁBIL | D7: =COUNTIFS(PLANIFICACION_MENSUAL!$E$2:$E$433,$A7,PLANIFICACION_MENSUAL!$J$2:$J$433,"<="&(D$1+0.0001),PLANIFICACION_MENSUAL!$K$2:$K$433,">"&(D$1+0.0001)) | E7: =COUNTIFS(PLANIFICACION_MENSUAL!$E$2:$E$433,$A7,PLANIFICACION_MENSUAL!$J$2:$J$433,"<="&(E$1+0.0001),PLANIFICACION_MENSUAL!$K$2:$K$433,">"&(E$1+0.0001)) | F7: =COUNTIFS(PLANIFICACION_MENSUAL!$E$2:$E$433,$A7,PLANIFICACION_MENSUAL!$J$2:$J$433,"<="&(F$1+0.0001),PLANIFICACION_MENSUAL!$K$2:$K$433,">"&(F$1+0.0001)) | G7: =COUNTIFS(PLANIFICACION_MENSUAL!$E$2:$E$433,$A7,PLANIFICACION_MENSUAL!$J$2:$J$433,"<="&(G$1+0.0001),PLANIFICACION_MENSUAL!$K$2:$K$433,">"&(G$1+0.0001)) | H7: =COUNTIFS(PLANIFICACION_MENSUAL!$E$2:$E$433,$A7,PLANIFICACION_MENSUAL!$J$2:$J$433,"<="&(H$1+0.0001),PLANIFICACION_MENSUAL!$K$2:$K$433,">"&(H$1+0.0001)) | I7: =COUNTIFS(PLANIFICACION_MENSUAL!$E$2:$E$433,$A7,PLANIFICACION_MENSUAL!$J$2:$J$433,"<="&(I$1+0.0001),PLANIFICACION_MENSUAL!$K$2:$K$433,">"&(I$1+0.0001)) | J7: =COUNTIFS(PLANIFICACION_MENSUAL!$E$2:$E$433,$A7,PLANIFICACION_MENSUAL!$J$2:$J$433,"<="&(J$1+0.0001),PLANIFICACION_MENSUAL!$K$2:$K$433,">"&(J$1+0.0001)) | K7: =COUNTIFS(PLANIFICACION_MENSUAL!$E$2:$E$433,$A7,PLANIFICACION_MENSUAL!$J$2:$J$433,"<="&(K$1+0.0001),PLANIFICACION_MENSUAL!$K$2:$K$433,">"&(K$1+0.0001)) | ... O7: =COUNTIFS(PLANIFICACION_MENSUAL!$E$2:$E$433,$A7,PLANIFICACION_MENSUAL!$J$2:$J$433,"<="&(O$1+0.0001),PLANIFICACION_MENSUAL!$K$2:$K$433,">"&(O$1+0.0001)) | P7: =COUNTIFS(PLANIFICACION_MENSUAL!$E$2:$E$433,$A7,PLANIFICACION_MENSUAL!$I$2:$I$433,"TRABAJA")
A8: 46303 | B8: Jueves | C8: HÁBIL | D8: =COUNTIFS(PLANIFICACION_MENSUAL!$E$2:$E$433,$A8,PLANIFICACION_MENSUAL!$J$2:$J$433,"<="&(D$1+0.0001),PLANIFICACION_MENSUAL!$K$2:$K$433,">"&(D$1+0.0001)) | E8: =COUNTIFS(PLANIFICACION_MENSUAL!$E$2:$E$433,$A8,PLANIFICACION_MENSUAL!$J$2:$J$433,"<="&(E$1+0.0001),PLANIFICACION_MENSUAL!$K$2:$K$433,">"&(E$1+0.0001)) | F8: =COUNTIFS(PLANIFICACION_MENSUAL!$E$2:$E$433,$A8,PLANIFICACION_MENSUAL!$J$2:$J$433,"<="&(F$1+0.0001),PLANIFICACION_MENSUAL!$K$2:$K$433,">"&(F$1+0.0001)) | G8: =COUNTIFS(PLANIFICACION_MENSUAL!$E$2:$E$433,$A8,PLANIFICACION_MENSUAL!$J$2:$J$433,"<="&(G$1+0.0001),PLANIFICACION_MENSUAL!$K$2:$K$433,">"&(G$1+0.0001)) | H8: =COUNTIFS(PLANIFICACION_MENSUAL!$E$2:$E$433,$A8,PLANIFICACION_MENSUAL!$J$2:$J$433,"<="&(H$1+0.0001),PLANIFICACION_MENSUAL!$K$2:$K$433,">"&(H$1+0.0001)) | I8: =COUNTIFS(PLANIFICACION_MENSUAL!$E$2:$E$433,$A8,PLANIFICACION_MENSUAL!$J$2:$J$433,"<="&(I$1+0.0001),PLANIFICACION_MENSUAL!$K$2:$K$433,">"&(I$1+0.0001)) | J8: =COUNTIFS(PLANIFICACION_MENSUAL!$E$2:$E$433,$A8,PLANIFICACION_MENSUAL!$J$2:$J$433,"<="&(J$1+0.0001),PLANIFICACION_MENSUAL!$K$2:$K$433,">"&(J$1+0.0001)) | K8: =COUNTIFS(PLANIFICACION_MENSUAL!$E$2:$E$433,$A8,PLANIFICACION_MENSUAL!$J$2:$J$433,"<="&(K$1+0.0001),PLANIFICACION_MENSUAL!$K$2:$K$433,">"&(K$1+0.0001)) | ... O8: =COUNTIFS(PLANIFICACION_MENSUAL!$E$2:$E$433,$A8,PLANIFICACION_MENSUAL!$J$2:$J$433,"<="&(O$1+0.0001),PLANIFICACION_MENSUAL!$K$2:$K$433,">"&(O$1+0.0001)) | P8: =COUNTIFS(PLANIFICACION_MENSUAL!$E$2:$E$433,$A8,PLANIFICACION_MENSUAL!$I$2:$I$433,"TRABAJA")
A9: 46304 | B9: Viernes | C9: HÁBIL | D9: =COUNTIFS(PLANIFICACION_MENSUAL!$E$2:$E$433,$A9,PLANIFICACION_MENSUAL!$J$2:$J$433,"<="&(D$1+0.0001),PLANIFICACION_MENSUAL!$K$2:$K$433,">"&(D$1+0.0001)) | E9: =COUNTIFS(PLANIFICACION_MENSUAL!$E$2:$E$433,$A9,PLANIFICACION_MENSUAL!$J$2:$J$433,"<="&(E$1+0.0001),PLANIFICACION_MENSUAL!$K$2:$K$433,">"&(E$1+0.0001)) | F9: =COUNTIFS(PLANIFICACION_MENSUAL!$E$2:$E$433,$A9,PLANIFICACION_MENSUAL!$J$2:$J$433,"<="&(F$1+0.0001),PLANIFICACION_MENSUAL!$K$2:$K$433,">"&(F$1+0.0001)) | G9: =COUNTIFS(PLANIFICACION_MENSUAL!$E$2:$E$433,$A9,PLANIFICACION_MENSUAL!$J$2:$J$433,"<="&(G$1+0.0001),PLANIFICACION_MENSUAL!$K$2:$K$433,">"&(G$1+0.0001)) | H9: =COUNTIFS(PLANIFICACION_MENSUAL!$E$2:$E$433,$A9,PLANIFICACION_MENSUAL!$J$2:$J$433,"<="&(H$1+0.0001),PLANIFICACION_MENSUAL!$K$2:$K$433,">"&(H$1+0.0001)) | I9: =COUNTIFS(PLANIFICACION_MENSUAL!$E$2:$E$433,$A9,PLANIFICACION_MENSUAL!$J$2:$J$433,"<="&(I$1+0.0001),PLANIFICACION_MENSUAL!$K$2:$K$433,">"&(I$1+0.0001)) | J9: =COUNTIFS(PLANIFICACION_MENSUAL!$E$2:$E$433,$A9,PLANIFICACION_MENSUAL!$J$2:$J$433,"<="&(J$1+0.0001),PLANIFICACION_MENSUAL!$K$2:$K$433,">"&(J$1+0.0001)) | K9: =COUNTIFS(PLANIFICACION_MENSUAL!$E$2:$E$433,$A9,PLANIFICACION_MENSUAL!$J$2:$J$433,"<="&(K$1+0.0001),PLANIFICACION_MENSUAL!$K$2:$K$433,">"&(K$1+0.0001)) | ... O9: =COUNTIFS(PLANIFICACION_MENSUAL!$E$2:$E$433,$A9,PLANIFICACION_MENSUAL!$J$2:$J$433,"<="&(O$1+0.0001),PLANIFICACION_MENSUAL!$K$2:$K$433,">"&(O$1+0.0001)) | P9: =COUNTIFS(PLANIFICACION_MENSUAL!$E$2:$E$433,$A9,PLANIFICACION_MENSUAL!$I$2:$I$433,"TRABAJA")
A10: 46305 | B10: Sábado | C10: SÁBADO | D10: =COUNTIFS(PLANIFICACION_MENSUAL!$E$2:$E$433,$A10,PLANIFICACION_MENSUAL!$J$2:$J$433,"<="&(D$1+0.0001),PLANIFICACION_MENSUAL!$K$2:$K$433,">"&(D$1+0.0001)) | E10: =COUNTIFS(PLANIFICACION_MENSUAL!$E$2:$E$433,$A10,PLANIFICACION_MENSUAL!$J$2:$J$433,"<="&(E$1+0.0001),PLANIFICACION_MENSUAL!$K$2:$K$433,">"&(E$1+0.0001)) | F10: =COUNTIFS(PLANIFICACION_MENSUAL!$E$2:$E$433,$A10,PLANIFICACION_MENSUAL!$J$2:$J$433,"<="&(F$1+0.0001),PLANIFICACION_MENSUAL!$K$2:$K$433,">"&(F$1+0.0001)) | G10: =COUNTIFS(PLANIFICACION_MENSUAL!$E$2:$E$433,$A10,PLANIFICACION_MENSUAL!$J$2:$J$433,"<="&(G$1+0.0001),PLANIFICACION_MENSUAL!$K$2:$K$433,">"&(G$1+0.0001)) | H10: =COUNTIFS(PLANIFICACION_MENSUAL!$E$2:$E$433,$A10,PLANIFICACION_MENSUAL!$J$2:$J$433,"<="&(H$1+0.0001),PLANIFICACION_MENSUAL!$K$2:$K$433,">"&(H$1+0.0001)) | I10: =COUNTIFS(PLANIFICACION_MENSUAL!$E$2:$E$433,$A10,PLANIFICACION_MENSUAL!$J$2:$J$433,"<="&(I$1+0.0001),PLANIFICACION_MENSUAL!$K$2:$K$433,">"&(I$1+0.0001)) | J10: =COUNTIFS(PLANIFICACION_MENSUAL!$E$2:$E$433,$A10,PLANIFICACION_MENSUAL!$J$2:$J$433,"<="&(J$1+0.0001),PLANIFICACION_MENSUAL!$K$2:$K$433,">"&(J$1+0.0001)) | K10: =COUNTIFS(PLANIFICACION_MENSUAL!$E$2:$E$433,$A10,PLANIFICACION_MENSUAL!$J$2:$J$433,"<="&(K$1+0.0001),PLANIFICACION_MENSUAL!$K$2:$K$433,">"&(K$1+0.0001)) | ... O10: =COUNTIFS(PLANIFICACION_MENSUAL!$E$2:$E$433,$A10,PLANIFICACION_MENSUAL!$J$2:$J$433,"<="&(O$1+0.0001),PLANIFICACION_MENSUAL!$K$2:$K$433,">"&(O$1+0.0001)) | P10: =COUNTIFS(PLANIFICACION_MENSUAL!$E$2:$E$433,$A10,PLANIFICACION_MENSUAL!$I$2:$I$433,"TRABAJA")
A11: 46307 | B11: Lunes | C11: FERIADO | D11: =COUNTIFS(PLANIFICACION_MENSUAL!$E$2:$E$433,$A11,PLANIFICACION_MENSUAL!$J$2:$J$433,"<="&(D$1+0.0001),PLANIFICACION_MENSUAL!$K$2:$K$433,">"&(D$1+0.0001)) | E11: =COUNTIFS(PLANIFICACION_MENSUAL!$E$2:$E$433,$A11,PLANIFICACION_MENSUAL!$J$2:$J$433,"<="&(E$1+0.0001),PLANIFICACION_MENSUAL!$K$2:$K$433,">"&(E$1+0.0001)) | F11: =COUNTIFS(PLANIFICACION_MENSUAL!$E$2:$E$433,$A11,PLANIFICACION_MENSUAL!$J$2:$J$433,"<="&(F$1+0.0001),PLANIFICACION_MENSUAL!$K$2:$K$433,">"&(F$1+0.0001)) | G11: =COUNTIFS(PLANIFICACION_MENSUAL!$E$2:$E$433,$A11,PLANIFICACION_MENSUAL!$J$2:$J$433,"<="&(G$1+0.0001),PLANIFICACION_MENSUAL!$K$2:$K$433,">"&(G$1+0.0001)) | H11: =COUNTIFS(PLANIFICACION_MENSUAL!$E$2:$E$433,$A11,PLANIFICACION_MENSUAL!$J$2:$J$433,"<="&(H$1+0.0001),PLANIFICACION_MENSUAL!$K$2:$K$433,">"&(H$1+0.0001)) | I11: =COUNTIFS(PLANIFICACION_MENSUAL!$E$2:$E$433,$A11,PLANIFICACION_MENSUAL!$J$2:$J$433,"<="&(I$1+0.0001),PLANIFICACION_MENSUAL!$K$2:$K$433,">"&(I$1+0.0001)) | J11: =COUNTIFS(PLANIFICACION_MENSUAL!$E$2:$E$433,$A11,PLANIFICACION_MENSUAL!$J$2:$J$433,"<="&(J$1+0.0001),PLANIFICACION_MENSUAL!$K$2:$K$433,">"&(J$1+0.0001)) | K11: =COUNTIFS(PLANIFICACION_MENSUAL!$E$2:$E$433,$A11,PLANIFICACION_MENSUAL!$J$2:$J$433,"<="&(K$1+0.0001),PLANIFICACION_MENSUAL!$K$2:$K$433,">"&(K$1+0.0001)) | ... O11: =COUNTIFS(PLANIFICACION_MENSUAL!$E$2:$E$433,$A11,PLANIFICACION_MENSUAL!$J$2:$J$433,"<="&(O$1+0.0001),PLANIFICACION_MENSUAL!$K$2:$K$433,">"&(O$1+0.0001)) | P11: =COUNTIFS(PLANIFICACION_MENSUAL!$E$2:$E$433,$A11,PLANIFICACION_MENSUAL!$I$2:$I$433,"TRABAJA")
A12: 46308 | B12: Martes | C12: HÁBIL | D12: =COUNTIFS(PLANIFICACION_MENSUAL!$E$2:$E$433,$A12,PLANIFICACION_MENSUAL!$J$2:$J$433,"<="&(D$1+0.0001),PLANIFICACION_MENSUAL!$K$2:$K$433,">"&(D$1+0.0001)) | E12: =COUNTIFS(PLANIFICACION_MENSUAL!$E$2:$E$433,$A12,PLANIFICACION_MENSUAL!$J$2:$J$433,"<="&(E$1+0.0001),PLANIFICACION_MENSUAL!$K$2:$K$433,">"&(E$1+0.0001)) | F12: =COUNTIFS(PLANIFICACION_MENSUAL!$E$2:$E$433,$A12,PLANIFICACION_MENSUAL!$J$2:$J$433,"<="&(F$1+0.0001),PLANIFICACION_MENSUAL!$K$2:$K$433,">"&(F$1+0.0001)) | G12: =COUNTIFS(PLANIFICACION_MENSUAL!$E$2:$E$433,$A12,PLANIFICACION_MENSUAL!$J$2:$J$433,"<="&(G$1+0.0001),PLANIFICACION_MENSUAL!$K$2:$K$433,">"&(G$1+0.0001)) | H12: =COUNTIFS(PLANIFICACION_MENSUAL!$E$2:$E$433,$A12,PLANIFICACION_MENSUAL!$J$2:$J$433,"<="&(H$1+0.0001),PLANIFICACION_MENSUAL!$K$2:$K$433,">"&(H$1+0.0001)) | I12: =COUNTIFS(PLANIFICACION_MENSUAL!$E$2:$E$433,$A12,PLANIFICACION_MENSUAL!$J$2:$J$433,"<="&(I$1+0.0001),PLANIFICACION_MENSUAL!$K$2:$K$433,">"&(I$1+0.0001)) | J12: =COUNTIFS(PLANIFICACION_MENSUAL!$E$2:$E$433,$A12,PLANIFICACION_MENSUAL!$J$2:$J$433,"<="&(J$1+0.0001),PLANIFICACION_MENSUAL!$K$2:$K$433,">"&(J$1+0.0001)) | K12: =COUNTIFS(PLANIFICACION_MENSUAL!$E$2:$E$433,$A12,PLANIFICACION_MENSUAL!$J$2:$J$433,"<="&(K$1+0.0001),PLANIFICACION_MENSUAL!$K$2:$K$433,">"&(K$1+0.0001)) | ... O12: =COUNTIFS(PLANIFICACION_MENSUAL!$E$2:$E$433,$A12,PLANIFICACION_MENSUAL!$J$2:$J$433,"<="&(O$1+0.0001),PLANIFICACION_MENSUAL!$K$2:$K$433,">"&(O$1+0.0001)) | P12: =COUNTIFS(PLANIFICACION_MENSUAL!$E$2:$E$433,$A12,PLANIFICACION_MENSUAL!$I$2:$I$433,"TRABAJA")
A13: 46309 | B13: Miércoles | C13: HÁBIL | D13: =COUNTIFS(PLANIFICACION_MENSUAL!$E$2:$E$433,$A13,PLANIFICACION_MENSUAL!$J$2:$J$433,"<="&(D$1+0.0001),PLANIFICACION_MENSUAL!$K$2:$K$433,">"&(D$1+0.0001)) | E13: =COUNTIFS(PLANIFICACION_MENSUAL!$E$2:$E$433,$A13,PLANIFICACION_MENSUAL!$J$2:$J$433,"<="&(E$1+0.0001),PLANIFICACION_MENSUAL!$K$2:$K$433,">"&(E$1+0.0001)) | F13: =COUNTIFS(PLANIFICACION_MENSUAL!$E$2:$E$433,$A13,PLANIFICACION_MENSUAL!$J$2:$J$433,"<="&(F$1+0.0001),PLANIFICACION_MENSUAL!$K$2:$K$433,">"&(F$1+0.0001)) | G13: =COUNTIFS(PLANIFICACION_MENSUAL!$E$2:$E$433,$A13,PLANIFICACION_MENSUAL!$J$2:$J$433,"<="&(G$1+0.0001),PLANIFICACION_MENSUAL!$K$2:$K$433,">"&(G$1+0.0001)) | H13: =COUNTIFS(PLANIFICACION_MENSUAL!$E$2:$E$433,$A13,PLANIFICACION_MENSUAL!$J$2:$J$433,"<="&(H$1+0.0001),PLANIFICACION_MENSUAL!$K$2:$K$433,">"&(H$1+0.0001)) | I13: =COUNTIFS(PLANIFICACION_MENSUAL!$E$2:$E$433,$A13,PLANIFICACION_MENSUAL!$J$2:$J$433,"<="&(I$1+0.0001),PLANIFICACION_MENSUAL!$K$2:$K$433,">"&(I$1+0.0001)) | J13: =COUNTIFS(PLANIFICACION_MENSUAL!$E$2:$E$433,$A13,PLANIFICACION_MENSUAL!$J$2:$J$433,"<="&(J$1+0.0001),PLANIFICACION_MENSUAL!$K$2:$K$433,">"&(J$1+0.0001)) | K13: =COUNTIFS(PLANIFICACION_MENSUAL!$E$2:$E$433,$A13,PLANIFICACION_MENSUAL!$J$2:$J$433,"<="&(K$1+0.0001),PLANIFICACION_MENSUAL!$K$2:$K$433,">"&(K$1+0.0001)) | ... O13: =COUNTIFS(PLANIFICACION_MENSUAL!$E$2:$E$433,$A13,PLANIFICACION_MENSUAL!$J$2:$J$433,"<="&(O$1+0.0001),PLANIFICACION_MENSUAL!$K$2:$K$433,">"&(O$1+0.0001)) | P13: =COUNTIFS(PLANIFICACION_MENSUAL!$E$2:$E$433,$A13,PLANIFICACION_MENSUAL!$I$2:$I$433,"TRABAJA")
... A28: 46326 | B28: Sábado | C28: FERIADO | D28: =COUNTIFS(PLANIFICACION_MENSUAL!$E$2:$E$433,$A28,PLANIFICACION_MENSUAL!$J$2:$J$433,"<="&(D$1+0.0001),PLANIFICACION_MENSUAL!$K$2:$K$433,">"&(D$1+0.0001)) | E28: =COUNTIFS(PLANIFICACION_MENSUAL!$E$2:$E$433,$A28,PLANIFICACION_MENSUAL!$J$2:$J$433,"<="&(E$1+0.0001),PLANIFICACION_MENSUAL!$K$2:$K$433,">"&(E$1+0.0001)) | F28: =COUNTIFS(PLANIFICACION_MENSUAL!$E$2:$E$433,$A28,PLANIFICACION_MENSUAL!$J$2:$J$433,"<="&(F$1+0.0001),PLANIFICACION_MENSUAL!$K$2:$K$433,">"&(F$1+0.0001)) | G28: =COUNTIFS(PLANIFICACION_MENSUAL!$E$2:$E$433,$A28,PLANIFICACION_MENSUAL!$J$2:$J$433,"<="&(G$1+0.0001),PLANIFICACION_MENSUAL!$K$2:$K$433,">"&(G$1+0.0001)) | H28: =COUNTIFS(PLANIFICACION_MENSUAL!$E$2:$E$433,$A28,PLANIFICACION_MENSUAL!$J$2:$J$433,"<="&(H$1+0.0001),PLANIFICACION_MENSUAL!$K$2:$K$433,">"&(H$1+0.0001)) | I28: =COUNTIFS(PLANIFICACION_MENSUAL!$E$2:$E$433,$A28,PLANIFICACION_MENSUAL!$J$2:$J$433,"<="&(I$1+0.0001),PLANIFICACION_MENSUAL!$K$2:$K$433,">"&(I$1+0.0001)) | J28: =COUNTIFS(PLANIFICACION_MENSUAL!$E$2:$E$433,$A28,PLANIFICACION_MENSUAL!$J$2:$J$433,"<="&(J$1+0.0001),PLANIFICACION_MENSUAL!$K$2:$K$433,">"&(J$1+0.0001)) | K28: =COUNTIFS(PLANIFICACION_MENSUAL!$E$2:$E$433,$A28,PLANIFICACION_MENSUAL!$J$2:$J$433,"<="&(K$1+0.0001),PLANIFICACION_MENSUAL!$K$2:$K$433,">"&(K$1+0.0001)) | ... O28: =COUNTIFS(PLANIFICACION_MENSUAL!$E$2:$E$433,$A28,PLANIFICACION_MENSUAL!$J$2:$J$433,"<="&(O$1+0.0001),PLANIFICACION_MENSUAL!$K$2:$K$433,">"&(O$1+0.0001)) | P28: =COUNTIFS(PLANIFICACION_MENSUAL!$E$2:$E$433,$A28,PLANIFICACION_MENSUAL!$I$2:$I$433,"TRABAJA")
A29: MÍNIMO | D29: =MIN(D2:D28) | E29: =MIN(E2:E28) | F29: =MIN(F2:F28) | G29: =MIN(G2:G28) | H29: =MIN(H2:H28) | I29: =MIN(I2:I28) | J29: =MIN(J2:J28) | K29: =MIN(K2:K28) | ... P29: =MIN(P2:P28)

Sheet ALERTAS
A1: TIPO | B1: FECHA | C1: RUT | D1: NOMBRE | E1: DETALLE
A2: Sin alertas | E2: La planificación cumple todas las reglas.
